<?xml version="1.0" encoding="utf-8"?>
<robot name="strawberry_plant">
  <link name="world"/>
  <material name="Blue">
    <color rgba="0.28 0.52 0.92 1.0"/>0
  </material>
  <material name="red">
    <color rgba="0.9 0.2 0.2 1.0"/>0
  </material>
  <material name="green">
    <color rgba="0.25 0.9 0.2 1.0"/>0
  </material>

  <link name="Upperstem">
    <visual>
      <geometry>
        <sphere radius="0.01"/>
      </geometry>
      <origin rpy="0 0 0" xyz="0 0 0"/>
      <material name="green"/>
    </visual>
  </link>

  <joint name="joint0" type="fixed">
    <parent link="world"/>
    <child link="Upperstem"/>
    <origin rpy="0 0 0" xyz="0 0 0"/>
  </joint>

<!-- asdffffffffffffffffffffffffffffffffffffffffffffffffffffffffffffffffffffffffffffffffffffffff -->
<!-- asdffffffffffffffffffffffffffffffffffffffffffffffffffffffffffffffffffffffffffffffffffffffff -->
<!-- asdffffffffffffffffffffffffffffffffffffffffffffffffffffffffffffffffffffffffffffffffffffffff -->
<!-- asdffffffffffffffffffffffffffffffffffffffffffffffffffffffffffffffffffffffffffffffffffffffff -->

  <link name="stem">
    <visual>
      <geometry>
        <cylinder radius="0.001" length="0.13"/>
      </geometry>
      <origin rpy="1.57 0 0" xyz="0 0.075 0"/>
      <material name="green"/>
    </visual>
    <collision>
      <geometry>
        <cylinder radius="0.001" length="0.13"/>
      </geometry>
      <origin rpy="1.57 0 0" xyz="0 0.075 0"/>
    </collision>
    <inertial>
      <origin rpy="1.57 0 0" xyz="0 0.075 0"/>
      <mass value="0.01"/>
        <inertia  ixx="0.00001" ixy="0.0" ixz="0.0"
                  iyy="0.00001" iyz="0.0"
                  izz="0.00001" />    
    </inertial>
  </link>

  <link name="inner_jointlink_1"/>
  <joint name="innerjoint1" type="revolute" >
    <parent link="Upperstem" />
    <child link="inner_jointlink_1" />
    <origin xyz="0 0 0" rpy="0 0 0"/>
    <axis xyz="1 0 0" />
    <dynamics damping="0.0001" friction="0.0002"/>
    <limit
      lower="-10" upper="10"
      effort="1" velocity="0.1" />
  </joint>

  <link name="inner_jointlink_2"/>
  <joint name="innerjoint2" type="revolute" >
    <parent link="inner_jointlink_1" />
    <child link="inner_jointlink_2" />
    <origin xyz="0 0 0" rpy="0 0 0"/>
    <axis xyz="0 1 0" />
    <dynamics damping="0.0001" friction="0.0002"/>
    <limit
      lower="-10" upper="10"
      effort="1" velocity="0.1" />
  </joint>

  <joint name="innerjoint3" type="revolute" >
    <parent link="inner_jointlink_2" />
    <child link="stem" />
    <origin xyz="0 0 0" rpy="0 0 0"/>
    <axis xyz="0 0 1" />
    <dynamics damping="0.0001" friction="0.0002"/>
    <limit
      lower="-10" upper="10"
      effort="1" velocity="0.1" />
  </joint>


<!-- asdffffffffffffffffffffffffffffffffffffffffffffffffffffffffffffffffffffffffffffffffffffffff -->
<!-- asdffffffffffffffffffffffffffffffffffffffffffffffffffffffffffffffffffffffffffffffffffffffff -->
<!-- asdffffffffffffffffffffffffffffffffffffffffffffffffffffffffffffffffffffffffffffffffffffffff -->
<!-- asdffffffffffffffffffffffffffffffffffffffffffffffffffffffffffffffffffffffffffffffffffffffff -->



  <link name="strawberry">
    <visual>
      <geometry>
        <mesh filename="meshes/strawberry.obj" scale="0.01 0.01 0.01"/>
      </geometry>
      <origin rpy="1.57 0 0" xyz="-0.005 0.15 -0.005"/>
      <material name="red"/>
    </visual>
    <collision>
      <geometry>
        <mesh filename="meshes/strawberry.obj" scale="0.01 0.01 0.01"/>
      </geometry>
      <origin rpy="1.57 0 0" xyz="-0.005 0.15 -0.005"/>
    </collision>
    <inertial>
      <origin rpy="1.57 0 0" xyz="-0.005 0.15 -0.005"/>
      <mass value="0.04"/>
        <inertia  ixx="0.00001" ixy="0.0" ixz="0.0"
                  iyy="0.00001" iyz="0.0"
                  izz="0.00001" />    
    </inertial>
  </link>

  <joint name="joint2" type="fixed">
    <parent link="stem"/>
    <child link="strawberry"/>
    <origin rpy="0 0 0" xyz="0 0 0"/>
  </joint>

</robot>
