<?xml version="1.0" ?>
<!-- =================================================================================== -->
<!-- |    This document was autogenerated by xacro from panda_arm_hand.urdf.xacro      | -->
<!-- |    EDITING THIS FILE BY HAND IS NOT RECOMMENDED                                 | -->
<!-- =================================================================================== -->
<robot name="panda" xmlns:xacro="http://www.ros.org/wiki/xacro">
  <link name="panda_link0">
  	<inertial>
      <origin rpy="0 0 0" xyz="0 0 0.05"/>
       <mass value="2.9"/>
       <inertia ixx="0.1" ixy="0" ixz="0" iyy="0.1" iyz="0" izz="0.1"/>
    </inertial>
    <visual>
      <geometry>
        <mesh filename="package://meshes/collision/link0.obj"/>
      </geometry>
      <material name="panda_white">
    		<color rgba="1. 1. 1. 1."/>
  		</material>
    </visual>
    <collision>
      <geometry>
        <mesh filename="package://meshes/collision/link0.obj"/>
      </geometry>
      <material name="panda_white"/>
    </collision>
  </link>
  <link name="panda_link1">
  	<inertial>
      <origin rpy="0 0 0" xyz="0 -0.04 -0.05"/>
       <mass value="2.7"/>
       <inertia ixx="0.1" ixy="0" ixz="0" iyy="0.1" iyz="0" izz="0.1"/>
    </inertial>
    <visual>
      <geometry>
        <mesh filename="package://meshes/visual/link1.obj"/>
      </geometry>
      <material name="panda_white"/>
    </visual>
    <collision>
      <geometry>
        <mesh filename="package://meshes/collision/link1.obj"/>
      </geometry>
      <material name="panda_white"/>
    </collision>
  </link>
  <joint name="panda_joint1" type="revolute">
    <safety_controller k_position="100.0" k_velocity="40.0" soft_lower_limit="-2.8973" soft_upper_limit="2.8973"/>
    <origin rpy="0 0 0" xyz="0 0 0.333"/>
    <parent link="panda_link0"/>
    <child link="panda_link1"/>
    <axis xyz="0 0 1"/>
    <limit effort="87" lower="-2.9671" upper="2.9671" velocity="2.1750"/>
  </joint>
  <link name="panda_link2">
  	<inertial>
      <origin rpy="0 0 0" xyz="0 -0.04 0.06"/>
       <mass value="2.73"/>
       <inertia ixx="0.1" ixy="0" ixz="0" iyy="0.1" iyz="0" izz="0.1"/>
    </inertial>
    <visual>
      <geometry>
        <mesh filename="package://meshes/visual/link2.obj"/>
      </geometry>
      <material name="panda_white"/>
    </visual>
    <collision>
      <geometry>
        <mesh filename="package://meshes/collision/link2.obj"/>
      </geometry>
      <material name="panda_white"/>
    </collision>
  </link>
  <joint name="panda_joint2" type="revolute">
    <safety_controller k_position="100.0" k_velocity="40.0" soft_lower_limit="-1.7628" soft_upper_limit="1.7628"/>
    <origin rpy="-1.57079632679 0 0" xyz="0 0 0"/>
    <parent link="panda_link1"/>
    <child link="panda_link2"/>
    <axis xyz="0 0 1"/>
    <limit effort="87" lower="-1.8326" upper="1.8326" velocity="2.1750"/>
  </joint>
  <link name="panda_link3">
	  <inertial>
      <origin rpy="0 0 0" xyz="0.01 0.01 -0.05"/>
       <mass value="2.04"/>
       <inertia ixx="0.1" ixy="0" ixz="0" iyy="0.1" iyz="0" izz="0.1"/>
    </inertial>
    <visual>
      <geometry>
        <mesh filename="package://meshes/visual/link3.obj"/>
      </geometry>
      <material name="panda_red">
    		<color rgba="1. 1. 1. 1."/>
  		</material>
    </visual>
    <collision>
      <geometry>
        <mesh filename="package://meshes/collision/link3.obj"/>
      </geometry>
    </collision>
  </link>
  <joint name="panda_joint3" type="revolute">
    <safety_controller k_position="100.0" k_velocity="40.0" soft_lower_limit="-2.8973" soft_upper_limit="2.8973"/>
    <origin rpy="1.57079632679 0 0" xyz="0 -0.316 0"/>
    <parent link="panda_link2"/>
    <child link="panda_link3"/>
    <axis xyz="0 0 1"/>
    <limit effort="87" lower="-2.9671" upper="2.9671" velocity="2.1750"/>
  </joint>
  <link name="panda_link4">
  	<inertial>
      <origin rpy="0 0 0" xyz="-0.03 0.03 0.02"/>
       <mass value="2.08"/>
       <inertia ixx="0.1" ixy="0" ixz="0" iyy="0.1" iyz="0" izz="0.1"/>
    </inertial>
    <visual>
      <geometry>
        <mesh filename="package://meshes/visual/link4.obj"/>
      </geometry>
      <material name="panda_white"/>
    </visual>
    <collision>
      <geometry>
        <mesh filename="package://meshes/collision/link4.obj"/>
      </geometry>
      <material name="panda_white"/>
    </collision>
  </link>
  <joint name="panda_joint4" type="revolute">
    <safety_controller k_position="100.0" k_velocity="40.0" soft_lower_limit="-3.0718" soft_upper_limit="-0.0698"/>
    <origin rpy="1.57079632679 0 0" xyz="0.0825 0 0"/>
    <parent link="panda_link3"/>
    <child link="panda_link4"/>
    <axis xyz="0 0 1"/>
    <limit effort="87" lower="-3.1416" upper="0.0" velocity="2.1750"/>
  </joint>
  <link name="panda_link5">
  	<inertial>
      <origin rpy="0 0 0" xyz="0 0.04 -0.12"/>
       <mass value="3"/>
       <inertia ixx="0.1" ixy="0" ixz="0" iyy="0.1" iyz="0" izz="0.1"/>
    </inertial>
    <visual>
      <geometry>
        <mesh filename="package://meshes/visual/link5.obj"/>
      </geometry>
      <material name="panda_white"/>
    </visual>
    <collision>
      <geometry>
        <mesh filename="package://meshes/collision/link5.obj"/>
      </geometry>
      <material name="panda_white"/>
    </collision>
  </link>
  <joint name="panda_joint5" type="revolute">
    <safety_controller k_position="100.0" k_velocity="40.0" soft_lower_limit="-2.8973" soft_upper_limit="2.8973"/>
    <origin rpy="-1.57079632679 0 0" xyz="-0.0825 0.384 0"/>
    <parent link="panda_link4"/>
    <child link="panda_link5"/>
    <axis xyz="0 0 1"/>
    <limit effort="12" lower="-2.9671" upper="2.9671" velocity="2.6100"/>
  </joint>
  <link name="panda_link6">
  	<inertial>
      <origin rpy="0 0 0" xyz="0.04 0 0"/>
       <mass value="1.3"/>
       <inertia ixx="0.1" ixy="0" ixz="0" iyy="0.1" iyz="0" izz="0.1"/>
    </inertial>
    <visual>
      <geometry>
        <mesh filename="package://meshes/visual/link6.obj"/>
      </geometry>
      <material name="panda_white"/>
    </visual>
    <collision>
      <geometry>
        <mesh filename="package://meshes/collision/link6.obj"/>
      </geometry>
      <material name="panda_white"/>
    </collision>
  </link>
  <joint name="panda_joint6" type="revolute">
    <safety_controller k_position="100.0" k_velocity="40.0" soft_lower_limit="-0.0175" soft_upper_limit="3.7525"/>
    <origin rpy="1.57079632679 0 0" xyz="0 0 0"/>
    <parent link="panda_link5"/>
    <child link="panda_link6"/>
    <axis xyz="0 0 1"/>
    <limit effort="12" lower="-0.0873" upper="3.8223" velocity="2.6100"/>
  </joint>
  <link name="panda_link7">
  	<inertial>
      <origin rpy="0 0 0" xyz="0 0 0.08"/>
       <mass value=".2"/>
       <inertia ixx="0.1" ixy="0" ixz="0" iyy="0.1" iyz="0" izz="0.1"/>
    </inertial>
    <visual>
      <geometry>
        <mesh filename="package://meshes/collision/link7.obj"/>
      </geometry>
      <material name="panda_white"/>
    </visual>
    <collision>
      <geometry>
        <mesh filename="package://meshes/collision/link7.obj"/>
      </geometry>
      <material name="panda_white"/>
    </collision>
  </link>
  <joint name="panda_joint7" type="revolute">
    <safety_controller k_position="100.0" k_velocity="40.0" soft_lower_limit="-2.8973" soft_upper_limit="2.8973"/>
    <origin rpy="1.57079632679 0 0" xyz="0.088 0 0"/>
    <parent link="panda_link6"/>
    <child link="panda_link7"/>
    <axis xyz="0 0 1"/>
    <limit effort="12" lower="-2.9671" upper="2.9671" velocity="2.6100"/>
  </joint>
  <link name="panda_link8">
  	 <inertial>
      <origin rpy="0 0 0" xyz="0 0 0"/>
       <mass value="0.0"/>
       <inertia ixx="0.1" ixy="0" ixz="0" iyy="0.1" iyz="0" izz="0.1"/>
    </inertial>
  </link>
  <joint name="panda_joint8" type="fixed">
    <origin rpy="0 0 0" xyz="0 0 0.107"/>
    <parent link="panda_link7"/>
    <child link="panda_link8"/>
    <axis xyz="0 0 0"/>
  </joint>


  <!-- Dummy EE for planning -->
  <link name="dummy_ee">
    <inertial>
      <!-- <origin xyz="0 0 -0.785" rpy="0.08 0 0.11"/> -->
      <origin rpy="0 0 0" xyz="0 0 0"/>
      <mass value="0.0"/>
      <inertia
        ixx="1.0" ixy="0.0" ixz="0.0"
        iyy="1.0" iyz="0.0" 
        izz="1.0"/>
    </inertial>
    <visual>
      <geometry>
        <sphere radius="0.01"/>
      </geometry>
      <!-- <origin rpy="0 0 -0.785" xyz="0.08 0 0.11"/> -->
      <origin rpy="0 0 0" xyz="0 0 0"/>
      <material name="panda_white" />
    </visual>
  </link>
  <joint name="dummy_ee_joint" type="fixed">
    <parent link="panda_link8"/>
    <child link="dummy_ee"/>
    <origin xyz="0.0 0 0.13" rpy="0 0 0"/>
  </joint>



<!--   <link name="end_effector">
    <visual>
      <geometry>
        <sphere radius="0.05"/>
      </geometry>
      <origin rpy="1.57 0 0" xyz="0 0 0.03"/>
      <material name="red"/>
    </visual>
    <collision>
      <geometry>
        <sphere radius="0.05"/>
      </geometry>
      <origin rpy="0 0 0" xyz="0 0 0.03"/>
    </collision>
    <inertial>
      <origin rpy="0 0 0" xyz="0 0 0.03"/>
      <mass value="0.5"/>
      <inertia ixx="0.1" ixy="0" ixz="0" iyy="0.1" iyz="0" izz="0.1"/>   
    </inertial>
  </link>
  <joint name="panda_joint9" type="fixed">
    <origin rpy="0 0 0" xyz="0 0 0"/>
    <parent link="panda_link8"/>
    <child link="end_effector"/>
    <axis xyz="0 0 0"/>
  </joint> -->


  <!-- Base Housing -->
<!--   <link name="gripper_housing">
    <inertial> -->
      <!-- <origin xyz="0 0 -0.785" rpy="0.08 0 0.11"/> -->
     <!--  <origin rpy="0 0 0" xyz="0 0 0"/>
      <mass value="0.8"/>
      <inertia
        ixx="1.0" ixy="0.0" ixz="0.0"
        iyy="1.0" iyz="0.0" 
        izz="1.0"/>
    </inertial>
    <visual>
      <geometry>
        <mesh filename="package://meshes/visual/HOUSING.stl" />
      </geometry>
      --> <!-- <origin rpy="0 0 -0.785" xyz="0.08 0 0.11"/> -->
<!--       <origin rpy="0 0 0" xyz="0 0 0"/>
      <material name="panda_white" />
    </visual>
  </link>
  <joint name="gripper_arm_joint" type="fixed">
    <parent link="panda_link8"/>
    <child link="gripper_housing"/>
    <origin xyz="0.06 0 0.08" rpy="-2.35619 -1.5708 -0.785398"/>
  </joint> -->


  <!-- Base Housing -->
  <link name="gripper_housing">
    <inertial>
      <!-- <origin xyz="0 0 -0.785" rpy="0.08 0 0.11"/> -->
      <origin rpy="0 0 0" xyz="0 0 0"/>
      <mass value="0.8"/>
      <inertia
        ixx="1.0" ixy="0.0" ixz="0.0"
        iyy="1.0" iyz="0.0" 
        izz="1.0"/>
    </inertial>
    <visual>
      <geometry>
        <mesh filename="package://meshes/visual/HOUSING.stl" />
      </geometry>
      <!-- <origin rpy="0 0 -0.785" xyz="0.08 0 0.11"/> -->
      <origin rpy="0 0 0" xyz="0 0 0"/>
      <material name="panda_white" />
    </visual>
    <collision>
      <geometry>
        <mesh filename="package://meshes/visual/HOUSING.stl"/>
      </geometry>
      <material name="panda_white"/>
    </collision>
  </link>
  <joint name="gripper_arm_joint" type="fixed">
    <parent link="panda_link8"/>
    <child link="gripper_housing"/>
    <origin xyz="0.0 0 0.07" rpy="0 0 -0.785398"/>
  </joint>

    <!-- Cutting Finger -->
  <link name="cutting_finger">
    <inertial>
      <origin xyz="0.0 0.0 0.0" rpy="0.0 0.0 0.0"/>
      <mass value="0.008"/>
      <inertia 
        ixx="1.0" ixy="0.0" ixz="0.0" 
        iyy="1.0" iyz="0.0" 
        izz="1.0"/>
    </inertial>
    <visual>
      <origin xyz="0.0 0.0 0.0" rpy="0.0 0.0 0.0"/>
      <geometry>
        <mesh filename="package://meshes/visual/CUTTING_FINGER.stl" />
      </geometry>
      <material name="panda_white" />
    </visual>
    <collision>
      <geometry>
        <mesh filename="package://meshes/visual/CUTTING_FINGER.stl"/>
      </geometry>
      <material name="panda_white"/>
    </collision>
  </link>

  <joint name="cutting_finger_joint" type="fixed">
    <parent link="gripper_housing"/>
    <child link="cutting_finger"/>
    <origin xyz="-0.02 -0.035 0.01" rpy="0 0.872665 1.0472"/>
<!--     <axis xyz="0 1 0"/>
    <limit lower="-0.87" upper="0" effort="100" velocity="1"/> -->
  </joint>

  <!-- Inner Finger 1 -->
  <link name="inner_finger_1">
    <inertial>
      <origin xyz="0.0 0.0 0.0" rpy="0.0 0.0 0.0"/>
      <mass value="0.005"/>
      <inertia 
        ixx="1.0" ixy="0.0" ixz="0.0" 
        iyy="1.0" iyz="0.0" 
        izz="1.0"/>
    </inertial>
    <visual>
      <origin xyz="0.0 0.0 0.0" rpy="0.0 0.0 0.0"/>
      <geometry>
        <mesh filename="package://meshes/visual/INNER_FINGER.stl" />
      </geometry>
      <material name="panda_white" />
    </visual>
    <collision>
      <geometry>
        <mesh filename="package://meshes/visual/INNER_FINGER.stl"/>
      </geometry>
      <material name="panda_white"/>
    </collision>
  </link>

  <joint name="inner_finger_1_joint" type="fixed">
    <parent link="gripper_housing"/>
    <child link="inner_finger_1"/>
    <origin xyz="0.04 0 0.01" rpy="0 0.872665 3.14159"/>
<!--     <axis xyz="0 1 0"/>
    <limit lower="-0.87" upper="0" effort="100" velocity="1"/>
    <mimic joint="cutting_finger_joint" multiplier="1" offset="0" /> -->
  </joint>

  <!-- Inner Finger 2 -->
  <link name="inner_finger_2">
    <inertial>
      <origin xyz="0.0 0.0 0.0" rpy="0.0 0.0 0.0"/>
      <mass value="0.005"/>
      <inertia 
        ixx="1.0" ixy="0.0" ixz="0.0" 
        iyy="1.0" iyz="0.0" 
        izz="1.0"/>
    </inertial>
    <visual>
      <origin xyz="0.0 0.0 0.0" rpy="0.0 0.0 0.0"/>
      <geometry>
        <mesh filename="package://meshes/visual/MIRRORINNER_FINGER.stl" />
      </geometry>
      <material name="panda_white" />
    </visual>
    <collision>
      <geometry>
        <mesh filename="package://meshes/visual/MIRRORINNER_FINGER.stl"/>
      </geometry>
      <material name="panda_white"/>
    </collision>
  </link>
  
  <joint name="inner_finger_2_joint" type="fixed">
    <parent link="gripper_housing"/>
    <child link="inner_finger_2"/>
    <origin xyz="-0.02 0.035 0.01" rpy="0 0.872665 -1.0472"/>
<!--     <axis xyz="0 1 0"/>
    <limit lower="-0.87" upper="0" effort="100" velocity="1"/>
    <mimic joint="cutting_finger_joint" multiplier="1" offset="0" /> -->
  </joint>

  <!-- Outer Finger 1 -->
  <link name="outer_finger_1">
    <inertial>
      <origin xyz="0.0 0.0 0.0" rpy="0.0 0.0 0.0"/>
      <mass value="0.006"/>
      <inertia 
        ixx="1.0" ixy="0.0" ixz="0.0" 
        iyy="1.0" iyz="0.0" 
        izz="1.0"/>
    </inertial>
    <visual>
      <origin xyz="0.0 0.0 0.0" rpy="0.0 0.0 0.0"/>
      <geometry>
        <mesh filename="package://meshes/visual/OUTER_FINGER.stl" />
      </geometry>
      <material name="panda_white" />
    </visual>
    <collision>
      <geometry>
        <mesh filename="package://meshes/visual/OUTER_FINGER.stl"/>
      </geometry>
      <material name="panda_white"/>
    </collision>
  </link>

  <joint name="outer_finger_1_joint" type="fixed">
    <parent link="gripper_housing"/>
    <child link="outer_finger_1"/>
    <origin xyz="-0.04 0 0.01" rpy="0 0.785398 0"/>
<!--     <axis xyz="0 1 0"/>
    <limit lower="-0.79" upper="0" effort="100" velocity="1"/>
    <mimic joint="cutting_finger_joint" multiplier="1" offset="0" />    -->         
  </joint>

  <!-- Outer Finger 2 -->
  <link name="outer_finger_2">
    <inertial>
      <origin xyz="0.0 0.0 0.0" rpy="0.0 0.0 0.0"/>
      <mass value="0.006"/>
      <inertia 
        ixx="1.0" ixy="0.0" ixz="0.0" 
        iyy="1.0" iyz="0.0" 
        izz="1.0"/>
    </inertial>
    <visual>
      <origin xyz="0.0 0.0 0.0" rpy="0.0 0.0 0.0"/>
      <geometry>
        <mesh filename="package://meshes/visual/OUTER_FINGER.stl" />
      </geometry> 
      <material name="panda_white" />
    </visual>
    <collision>
      <geometry>
        <mesh filename="package://meshes/visual/OUTER_FINGER.stl"/>
      </geometry>
      <material name="panda_white"/>
    </collision>
  </link>

  <joint name="outer_finger_2_joint" type="fixed">
    <parent link="gripper_housing"/>
    <child link="outer_finger_2"/>
    <origin xyz="0.02 0.035 0.01" rpy="0 0.785398 -2.0944"/>
<!--     <axis xyz="0 1 0"/>
    <limit lower="-0.79" upper="0" effort="100" velocity="1"/>
    <mimic joint="cutting_finger_joint" multiplier="1" offset="0" /> -->
  </joint>

  <!-- Outer Finger 3 -->
  <link name="outer_finger_3">
    <inertial>
      <origin xyz="0.0 0.0 0.0" rpy="0.0 0.0 0.0"/>
      <mass value="0.006"/>
      <inertia 
        ixx="1.0" ixy="0.0" ixz="0.0" 
        iyy="1.0" iyz="0.0" 
        izz="1.0"/>
    </inertial>
    <visual>
      <origin xyz="0.0 0.0 0.0" rpy="0.0 0.0 0.0"/>
      <geometry>
        <mesh filename="package://meshes/visual/OUTER_FINGER.stl" />
      </geometry>
      <material name="panda_white" />
    </visual>
    <collision>
      <geometry>
        <mesh filename="package://meshes/visual/OUTER_FINGER.stl"/>
      </geometry>
      <material name="panda_white"/>
    </collision>
  </link>

  <joint name="outer_finger_3_joint" type="fixed">
    <parent link="gripper_housing"/>
    <child link="outer_finger_3"/>
    <origin xyz="0.02 -0.035 0.01" rpy="0 0.785398 2.0944"/>
<!--     <axis xyz="0 1 0"/>
    <limit lower="-0.79" upper="0" effort="100" velocity="1"/>
    <mimic joint="cutting_finger_joint" multiplier="1" offset="0" /> -->
  </joint>

<!-- Cutting Blade Right -->
  <link name="cutter_right">
    <inertial>
      <origin xyz="0.0 0.0 0.0" rpy="0.0 0.0 0.0"/>
      <mass value="0.006"/>
      <inertia 
        ixx="1.0" ixy="0.0" ixz="0.0" 
        iyy="1.0" iyz="0.0" 
        izz="1.0"/>
    </inertial>
    <visual>
      <origin xyz="0.0 0.0 0.0" rpy="0.0 0.0 0.0"/>
      <geometry>
        <mesh filename="package://meshes/visual/CUTTER_R.stl" />
      </geometry>
      <material name="panda_white" />
    </visual>
    <collision>
      <geometry>
        <mesh filename="package://meshes/visual/CUTTER_R.stl"/>
      </geometry>
      <material name="panda_white"/>
    </collision>
  </link>

  <joint name="right_cutter_joint" type="fixed">
    <parent link="cutting_finger"/>
    <child link="cutter_right"/>
    <origin xyz="0.004 -0.006 0.035" rpy="0 1.8326 0"/>
<!--     <axis xyz="0 0 1"/>
    <limit lower="-2.09" upper="0" effort="1000" velocity="0.7"/>
    <dynamics damping="0.02" friction="0.0" /> -->
  </joint>

<!-- Cutting Blade Left -->
<link name="cutter_left">
    <inertial>
      <origin xyz="0.0 0.0 0.0" rpy="0.0 0.0 0.0"/>
      <mass value="0.007"/>
      <inertia 
        ixx="1.0" ixy="0.0" ixz="0.0" 
        iyy="1.0" iyz="0.0" 
        izz="1.0"/>
    </inertial>
    <visual>
      <origin xyz="0.0 0.0 0.0" rpy="0.0 0.0 0.0"/>
      <geometry>
        <mesh filename="package://meshes/visual/CUTTER_L.stl" />
      </geometry>
      <material name="panda_white" />
    </visual>
    <collision>
      <geometry>
        <mesh filename="package://meshes/visual/CUTTER_L.stl"/>
      </geometry>
      <material name="panda_white"/>
    </collision>
  </link>

  <joint name="left_cutter_joint" type="fixed">
    <parent link="cutting_finger"/>
    <child link="cutter_left"/>
    <origin xyz="0.004 0.007 0.035" rpy="0 1.8326 0"/>
<!--     <axis xyz="0 0 1"/>
    <limit lower="0" upper="2.09" effort="100" velocity="0.7"/>
    <mimic joint="right_cutter_joint" multiplier="-1" offset="0" />
    <dynamics damping="0.02" friction="0.0" /> -->
  </joint>

<!-- Punnet Clamp -->
  <link name="punnet_clamp">
    <inertial>
      <origin xyz="0.0 0.0 0.0" rpy="0.0 0.0 0.0"/>
      <mass value="0.003"/>
      <inertia 
        ixx="1.0" ixy="0.0" ixz="0.0" 
        iyy="1.0" iyz="0.0" 
        izz="1.0"/>
    </inertial>
    <visual>
      <origin xyz="0.0 0.0 0.0" rpy="0.0 0.0 0.0"/>
      <geometry>
        <mesh filename="package://meshes/visual/BASKET_CLAMP.stl" />
      </geometry>
      <material name="panda_white" />
    </visual>
    <collision>
      <geometry>
        <mesh filename="package://meshes/visual/BASKET_CLAMP.stl"/>
      </geometry>
      <material name="panda_white"/>
    </collision>
  </link>

  <joint name="punnet_clamp_joint" type="fixed">
    <parent link="gripper_housing"/>
    <child link="punnet_clamp"/>
    <origin xyz="-0.023 0.003 -0.025" rpy="0 0 0"/>
<!--     <axis xyz="0 1 0"/>
    <limit lower="-1.57" upper="0" effort="100" velocity="1"/> -->
  </joint>

</robot> 
