<?xml version="1.0"?>
<robot name="cluster">
  <link name="world"/>
  <material name="Blue">
    <color rgba="0.28 0.52 0.92 1.0"/>0
  </material>
  <material name="Red">
    <color rgba="0.9 0.2 0.2 1.0"/>0
  </material>
  <material name="green">
    <color rgba="0.25 0.9 0.2 1.0"/>0
  </material>

  <link name="yball_stem1">
    <gravity>1</gravity>
    <inertial>
      <origin xyz="0 0 0" rpy="0 0 0"/>
      <mass value=".00001"/>
      <inertia ixx="0.0000004" ixy="0.0" ixz="0.0" iyy="0.0000004" iyz="0.0" izz="0.0000004" />
    </inertial>
    <visual><geometry><sphere radius=".00001"/></geometry></visual>
    <collision><geometry><sphere radius=".00001"/></geometry></collision>
  </link>

<!--   <joint name="stem1y" type="continuous" >
    <parent link="world" />
    <child link="yball_stem1" />
    <origin xyz="0 0 0" rpy="0 0 0"/>
    <axis xyz="1 1 1" />
    <dynamics damping="0.0001" friction="0.0002"/>
    <limit effort="1" velocity="0.1" />
  </joint> -->

  <joint name="stem1y" type="revolute" >
    <parent link="world" />
    <child link="yball_stem1" />
    <origin xyz="0 0 0" rpy="0 0 0"/>
    <axis xyz="1 0 0" />
    <dynamics damping="0.0001" friction="0.0002"/>
    <limit effort="1" velocity="0.1" />
  </joint>
  <link name="inner_joint_1"/>
  <joint name="stem2y" type="revolute" >
    <parent link="yball_stem1" />
    <child link="inner_joint_1" />
    <origin xyz="0 0 0" rpy="0 0 0"/>
    <axis xyz="0 1 0" />
    <dynamics damping="0.0001" friction="0.0002"/>
    <limit effort="1" velocity="0.1" />
  </joint>
  <link name="inner_joint_2"/>
  <joint name="stem3y" type="revolute" >
    <parent link="inner_joint_1" />
    <child link="inner_joint_2" />
    <origin xyz="0 0 0" rpy="0 0 0"/>
    <axis xyz="0 0 1" />
    <dynamics damping="0.0001" friction="0.0002"/>
    <limit effort="1" velocity="0.1" />
  </joint>



  <link name="xball_stem1">
    <gravity>1</gravity>
    <inertial>
      <origin xyz="0 0 0" rpy="0 0 0"/>
      <mass value=".00001"/>
      <inertia ixx="0.0000004" ixy="0.0" ixz="0.0" iyy="0.0000004" iyz="0.0" izz="0.0000004" />
    </inertial>
    <visual><geometry><sphere radius=".00001"/></geometry></visual>
    <collision><geometry><sphere radius=".00001"/></geometry></collision>
  </link>

  <joint name="stem1x" type="continuous" >
    <parent link="yball_stem1"/>
    <child link="xball_stem1"/>
    <origin xyz="0 0 0" rpy="0 0 0"/> 
    <axis xyz="1 1 1" />
    <dynamics damping="0.0001" friction="0.0002" />
    <limit effort="1" velocity="0.1" />
  </joint>

  <!-- Define stem of straw1 -->
  <link name="stem1">
    <inertial>
      <origin xyz="0 0 0" rpy="0 0 0"/>
      <mass value="0.0002"/>
      <inertia
        ixx="0.0000000005" ixy="0.0" ixz="0.0"
        iyy="0.0000000005" iyz="0.0" 
        izz="0.0000000005"/>
    </inertial>
    <collision>
      <geometry>
  		<cylinder length="0.15" radius="0.003"/>
      </geometry>
      <material name="green"/>
      <origin xyz="0 0 -0.075" rpy="0 0 0"/>
    </collision>
    <visual>
      <geometry>
  	<cylinder length="0.15" radius="0.003"/>
      </geometry>
      <material name="green"/>
      <origin xyz="0 0 -0.075" rpy="0 0 0"/>
    </visual>
  </link>
<!--   <gazebo reference="stem1">
    <mu1>0.01</mu1>
    <mu2>0.01</mu2>
    <selfCollide>true</selfCollide>
    <maxContacts>2</maxContacts>
    <minDepth>0</minDepth>
    <maxVel>0.01</maxVel>
    <kp  value="1" />
    <kd  value="0.1" />  
    <material>Gazebo/Green</material>
  </gazebo> -->

  <joint name="xball_stem1" type="fixed">
    <parent link="xball_stem1"/>
    <child link="stem1"/>
    <origin xyz="0 0 0" rpy="0 0 0"/>  
  </joint> 

  <!-- Define straw1 -->
  <link name="straw1">
    <gravity>1</gravity>
    <inertial>
      <origin xyz="0 0 0" rpy="0 0 0"/>
      <mass value="0.0002"/>
      <inertia
        ixx="0.00000018" ixy="0.0" ixz="0.0"
        iyy="0.00000018" iyz="0.0" 
        izz="0.00000018"/>
    </inertial>
    <collision>
      <geometry>
      	<sphere radius="0.015"/>
      </geometry>
    </collision>
    <visual>
      <geometry>
  		<sphere radius="0.015"/>
      </geometry>
      <material name="Red">
        <color rgba="1 0 0 1"/>
      </material>
    </visual>
  </link>
<!--   <gazebo reference="straw1">
    <mu1>0.01</mu1>
    <mu2>0.01</mu2>
    <selfCollide>true</selfCollide>
    <maxContacts>2</maxContacts>
    <minDepth>0</minDepth>
    <maxVel>0.01</maxVel>
    <kp  value="1" />
    <kd  value="0.1" />  
    <material>Gazebo/Red</material>
  </gazebo> -->

  <joint name="straw1_stem1" type="fixed"> 
    <parent link="stem1"/>
    <child link="straw1"/>
    <origin xyz="0 0 -0.15" rpy="0 0 0"/> 
  </joint> 

</robot>


